<?xml version="1.0" ?>
<robot name="robot" xmlns:xacro="http://www.ros.org/wiki/xacro">

<xacro:include filename="$(find robot_description)/urdf/materials.xacro" />
<xacro:include filename="$(find robot_description)/urdf/robot.trans" />
<xacro:include filename="$(find robot_description)/urdf/robot.gazebo" />
<link name="base_link">
  <inertial>
    <origin rpy="0 0 0" xyz="-0.019902403741442462 -0.026131815850244072 0.02238118207502583"/>
    <mass value="0.7310055412327093"/>
    <inertia ixx="0.000985" ixy="0.0" ixz="2.7e-05" iyy="0.001061" iyz="-4e-06" izz="0.001604"/>
  </inertial>
  <visual>
    <origin rpy="0 0 0" xyz="0 0 0"/>
    <geometry>
      <mesh filename="package://robot_description/meshes/base_link.stl" scale="0.001 0.001 0.001"/>
    </geometry>
    <material name="silver"/>
  </visual>
  <collision>
    <origin rpy="0 0 0" xyz="0 0 0"/>
    <geometry>
      <mesh filename="package://robot_description/meshes/base_link.stl" scale="0.001 0.001 0.001"/>
    </geometry>
  </collision>
</link>

<link name="NATHANwaist_1">
  <inertial>
    <origin rpy="0 0 0" xyz="0.0022441628498335066 0.007590344465981981 0.01877031829177992"/>
    <mass value="0.5674790951447787"/>
    <inertia ixx="0.000389" ixy="-1.2e-05" ixz="-5e-05" iyy="0.00049" iyz="-5.3e-05" izz="0.000447"/>
  </inertial>
  <visual>
    <origin rpy="0 0 0" xyz="0.019548 0.026486 -0.056"/>
    <geometry>
      <mesh filename="package://robot_description/meshes/NATHANwaist_1.stl" scale="0.001 0.001 0.001"/>
    </geometry>
    <material name="silver"/>
  </visual>
  <collision>
    <origin rpy="0 0 0" xyz="0.019548 0.026486 -0.056"/>
    <geometry>
      <mesh filename="package://robot_description/meshes/NATHANwaist_1.stl" scale="0.001 0.001 0.001"/>
    </geometry>
  </collision>
</link>

<link name="NATHANarm1_1">
  <inertial>
    <origin rpy="0 0 0" xyz="0.04849048815110292 -0.008282958375380033 0.034105993344051316"/>
    <mass value="0.4435773528478237"/>
    <inertia ixx="0.000286" ixy="1e-06" ixz="-0.00033" iyy="0.000787" iyz="0.0" izz="0.000536"/>
  </inertial>
  <visual>
    <origin rpy="0 0 0" xyz="0.005629 0.022537 -0.096277"/>
    <geometry>
      <mesh filename="package://robot_description/meshes/NATHANarm1_1.stl" scale="0.001 0.001 0.001"/>
    </geometry>
    <material name="silver"/>
  </visual>
  <collision>
    <origin rpy="0 0 0" xyz="0.005629 0.022537 -0.096277"/>
    <geometry>
      <mesh filename="package://robot_description/meshes/NATHANarm1_1.stl" scale="0.001 0.001 0.001"/>
    </geometry>
  </collision>
</link>

<link name="NATHANarm02_1">
  <inertial>
    <origin rpy="0 0 0" xyz="0.031227914013118252 0.009778981953459175 0.021821434108410226"/>
    <mass value="0.4469758277074998"/>
    <inertia ixx="0.000222" ixy="-6e-06" ixz="-0.000194" iyy="0.000527" iyz="-4e-06" izz="0.000364"/>
  </inertial>
  <visual>
    <origin rpy="0 0 0" xyz="-0.092669 0.022537 -0.165106"/>
    <geometry>
      <mesh filename="package://robot_description/meshes/NATHANarm02_1.stl" scale="0.001 0.001 0.001"/>
    </geometry>
    <material name="silver"/>
  </visual>
  <collision>
    <origin rpy="0 0 0" xyz="-0.092669 0.022537 -0.165106"/>
    <geometry>
      <mesh filename="package://robot_description/meshes/NATHANarm02_1.stl" scale="0.001 0.001 0.001"/>
    </geometry>
  </collision>
</link>

<link name="NATHANarm3_1">
  <inertial>
    <origin rpy="0 0 0" xyz="0.015052541891171806 0.007684277084908263 0.010347648118011255"/>
    <mass value="0.1425119969472937"/>
    <inertia ixx="3e-05" ixy="-5e-06" ixz="-8e-06" iyy="3.8e-05" iyz="1e-06" izz="2.9e-05"/>
  </inertial>
  <visual>
    <origin rpy="0 0 0" xyz="-0.169228 0.013037 -0.212243"/>
    <geometry>
      <mesh filename="package://robot_description/meshes/NATHANarm3_1.stl" scale="0.001 0.001 0.001"/>
    </geometry>
    <material name="silver"/>
  </visual>
  <collision>
    <origin rpy="0 0 0" xyz="-0.169228 0.013037 -0.212243"/>
    <geometry>
      <mesh filename="package://robot_description/meshes/NATHANarm3_1.stl" scale="0.001 0.001 0.001"/>
    </geometry>
  </collision>
</link>

<joint name="Rev1" type="continuous">
  <origin rpy="0 0 0" xyz="-0.019548 -0.026486 0.056"/>
  <parent link="base_link"/>
  <child link="NATHANwaist_1"/>
  <axis xyz="0.0 -0.0 1.0"/>
</joint>

<joint name="Rev2" type="revolute">
  <origin rpy="0 0 0" xyz="0.013919 0.003949 0.040277"/>
  <parent link="NATHANwaist_1"/>
  <child link="NATHANarm1_1"/>
  <axis xyz="0.0 -1.0 -0.0"/>
  <limit effort="100" lower="-0.698132" upper="2.356194" velocity="100"/>
</joint>

<joint name="Rev3" type="revolute">
  <origin rpy="0 0 0" xyz="0.098298 0.0 0.068829"/>
  <parent link="NATHANarm1_1"/>
  <child link="NATHANarm02_1"/>
  <axis xyz="-0.0 1.0 0.0"/>
  <limit effort="100" lower="-1.22173" upper="1.48353" velocity="100"/>
</joint>

<joint name="Rev4" type="continuous">
  <origin rpy="0 0 0" xyz="0.076559 0.0095 0.047137"/>
  <parent link="NATHANarm02_1"/>
  <child link="NATHANarm3_1"/>
  <axis xyz="0.819152 0.0 0.573576"/>
</joint>

</robot>
